Workbook
Name Slicer_Region: #N/A

Sheet Orders
A1: Row ID | B1: Order Priority | C1: Discount | D1: Unit Price | E1: Shipping Cost | F1: Customer ID | G1: Customer Name | H1: Ship Mode | I1: Customer Segment | J1: Product Category | K1: Product Sub-Category | L1: Product Container | M1: Product Name | N1: Product Base Margin | O1: Country | P1: Region | Q1: State or Province | R1: City | S1: Postal Code | T1: Order Date | U1: Ship Date | V1: Profit | W1: Quantity ordered new | X1: Sales | Y1: Order ID | Z1: Month | AA1: Profit margin | AB1: Returned | AC1: Manager
A2: 20847 | B2: High | C2: 0.01 | D2: 2.84 | E2: 0.93 | F2: 3 | G2: Bonnie Potter | H2: Express Air | I2: Corporate | J2: Office Supplies | K2: Pens & Art Supplies | L2: Wrap Bag | M2: SANFORD Liquid Accent™ Tank-Style Highlighters | N2: 0.54 | O2: United States | P2: West | Q2: Washington | R2: Anacortes | S2: 98221 | T2: 42011 | U2: 42012 | V2: 4.56 | W2: 4 | X2: 13.01 | Y2: 88522 | Z2: =TEXT(Superstone_data[[#This Row],[Order Date]],"mmm") -> Jan | AA2: =Superstone_data[[#This Row],[Profit]]/Superstone_data[[#This Row],[Sales]] -> 0.35049962 | AB2: =IFERROR(VLOOKUP(Superstone_data[[#This Row],[Order ID]], Returns!A:B, 2, FALSE), "No") -> No | AC2: =VLOOKUP(Superstone_data[[#This Row],[Region]], Users!A:B, 2, FALSE) -> William
A3: 20228 | B3: Not Specified | C3: 0.02 | D3: 500.98 | E3: 26 | F3: 5 | G3: Ronnie Proctor | H3: Delivery Truck | I3: Home Office | J3: Furniture | K3: Chairs & Chairmats | L3: Jumbo Drum | M3: Global Troy™ Executive Leather Low-Back Tilter | N3: 0.6 | O3: United States | P3: West | Q3: California | R3: San Gabriel | S3: 91776 | T3: 42168 | U3: 42170 | V3: 4390.3665 | W3: 12 | X3: 6362.85 | Y3: 90193 | Z3: =TEXT(Superstone_data[[#This Row],[Order Date]],"mmm") -> Jun | AA3: =Superstone_data[[#This Row],[Profit]]/Superstone_data[[#This Row],[Sales]] -> 0.69 | AB3: =IFERROR(VLOOKUP(Superstone_data[[#This Row],[Order ID]], Returns!A:B, 2, FALSE), "No") -> No | AC3: =VLOOKUP(Superstone_data[[#This Row],[Region]], Users!A:B, 2, FALSE) -> William
A4: 21776 | B4: Critical | C4: 0.06 | D4: 9.48 | E4: 7.29 | F4: 11 | G4: Marcus Dunlap | H4: Regular Air | I4: Home Office | J4: Furniture | K4: Office Furnishings | L4: Small Pack | M4: DAX Two-Tone Rosewood/Black Document Frame, Desktop, 5 x 7 | N4: 0.45 | O4: United States | P4: East | Q4: New Jersey | R4: Roselle | S4: 7203 | T4: 42050 | U4: 42052 | V4: -53.8096 | W4: 22 | X4: 211.15 | Y4: 90192 | Z4: =TEXT(Superstone_data[[#This Row],[Order Date]],"mmm") -> Feb | AA4: =Superstone_data[[#This Row],[Profit]]/Superstone_data[[#This Row],[Sales]] -> -0.25484063 | AB4: =IFERROR(VLOOKUP(Superstone_data[[#This Row],[Order ID]], Returns!A:B, 2, FALSE), "No") -> No | AC4: =VLOOKUP(Superstone_data[[#This Row],[Region]], Users!A:B, 2, FALSE) -> Erin
A5: 24844 | B5: Medium | C5: 0.09 | D5: 78.69 | E5: 19.99 | F5: 14 | G5: Gwendolyn F Tyson | H5: Regular Air | I5: Small Business | J5: Furniture | K5: Office Furnishings | L5: Small Box | M5: Howard Miller 12-3/4 Diameter Accuwave DS ™ Wall Clock | N5: 0.43 | O5: United States | P5: Central | Q5: Minnesota | R5: Prior Lake | S5: 55372 | T5: 42136 | U5: 42138 | V5: 803.4705 | W5: 16 | X5: 1164.45 | Y5: 86838 | Z5: =TEXT(Superstone_data[[#This Row],[Order Date]],"mmm") -> May | AA5: =Superstone_data[[#This Row],[Profit]]/Superstone_data[[#This Row],[Sales]] -> 0.69 | AB5: =IFERROR(VLOOKUP(Superstone_data[[#This Row],[Order ID]], Returns!A:B, 2, FALSE), "No") -> No | AC5: =VLOOKUP(Superstone_data[[#This Row],[Region]], Users!A:B, 2, FALSE) -> Chris
A6: 24846 | B6: Medium | C6: 0.08 | D6: 3.28 | E6: 2.31 | F6: 14 | G6: Gwendolyn F Tyson | H6: Regular Air | I6: Small Business | J6: Office Supplies | K6: Pens & Art Supplies | L6: Wrap Bag | M6: Newell 321 | N6: 0.56 | O6: United States | P6: Central | Q6: Minnesota | R6: Prior Lake | S6: 55372 | T6: 42136 | U6: 42137 | V6: -24.03 | W6: 7 | X6: 22.23 | Y6: 86838 | Z6: =TEXT(Superstone_data[[#This Row],[Order Date]],"mmm") -> May | AA6: =Superstone_data[[#This Row],[Profit]]/Superstone_data[[#This Row],[Sales]] -> -1.0809717 | AB6: =IFERROR(VLOOKUP(Superstone_data[[#This Row],[Order ID]], Returns!A:B, 2, FALSE), "No") -> No | AC6: =VLOOKUP(Superstone_data[[#This Row],[Region]], Users!A:B, 2, FALSE) -> Chris
A7: 24847 | B7: Medium | C7: 0.05 | D7: 3.28 | E7: 4.2 | F7: 14 | G7: Gwendolyn F Tyson | H7: Regular Air | I7: Small Business | J7: Office Supplies | K7: Pens & Art Supplies | L7: Wrap Bag | M7: Newell 351 | N7: 0.56 | O7: United States | P7: Central | Q7: Minnesota | R7: Prior Lake | S7: 55372 | T7: 42136 | U7: 42137 | V7: -37.03 | W7: 4 | X7: 13.99 | Y7: 86838 | Z7: =TEXT(Superstone_data[[#This Row],[Order Date]],"mmm") -> May | AA7: =Superstone_data[[#This Row],[Profit]]/Superstone_data[[#This Row],[Sales]] -> -2.6468906 | AB7: =IFERROR(VLOOKUP(Superstone_data[[#This Row],[Order ID]], Returns!A:B, 2, FALSE), "No") -> No | AC7: =VLOOKUP(Superstone_data[[#This Row],[Region]], Users!A:B, 2, FALSE) -> Chris
A8: 24848 | B8: Medium | C8: 0.05 | D8: 3.58 | E8: 1.63 | F8: 14 | G8: Gwendolyn F Tyson | H8: Regular Air | I8: Small Business | J8: Office Supplies | K8: Rubber Bands | L8: Wrap Bag | M8: OIC Colored Binder Clips, Assorted Sizes | N8: 0.36 | O8: United States | P8: Central | Q8: Minnesota | R8: Prior Lake | S8: 55372 | T8: 42136 | U8: 42137 | V8: -0.71 | W8: 4 | X8: 14.26 | Y8: 86838 | Z8: =TEXT(Superstone_data[[#This Row],[Order Date]],"mmm") -> May | AA8: =Superstone_data[[#This Row],[Profit]]/Superstone_data[[#This Row],[Sales]] -> -0.049789621 | AB8: =IFERROR(VLOOKUP(Superstone_data[[#This Row],[Order ID]], Returns!A:B, 2, FALSE), "No") -> No | AC8: =VLOOKUP(Superstone_data[[#This Row],[Region]], Users!A:B, 2, FALSE) -> Chris
A9: 18181 | B9: Critical | C9: 0 | D9: 4.42 | E9: 4.99 | F9: 15 | G9: Timothy Reese | H9: Regular Air | I9: Small Business | J9: Office Supplies | K9: Envelopes | L9: Small Box | M9: Grip Seal Envelopes | N9: 0.38 | O9: United States | P9: East | Q9: New York | R9: Smithtown | S9: 11787 | T9: 42102 | U9: 42103 | V9: -59.82 | W9: 7 | X9: 33.47 | Y9: 86837 | Z9: =TEXT(Superstone_data[[#This Row],[Order Date]],"mmm") -> Apr | AA9: =Superstone_data[[#This Row],[Profit]]/Superstone_data[[#This Row],[Sales]] -> -1.7872722 | AB9: =IFERROR(VLOOKUP(Superstone_data[[#This Row],[Order ID]], Returns!A:B, 2, FALSE), "No") -> No | AC9: =VLOOKUP(Superstone_data[[#This Row],[Region]], Users!A:B, 2, FALSE) -> Erin
A10: 20925 | B10: Medium | C10: 0.01 | D10: 35.94 | E10: 6.66 | F10: 15 | G10: Timothy Reese | H10: Regular Air | I10: Small Business | J10: Office Supplies | K10: Envelopes | L10: Small Box | M10: Tyvek ® Top-Opening Peel & Seel ® Envelopes, Gray | N10: 0.4 | O10: United States | P10: East | Q10: New York | R10: Smithtown | S10: 11787 | T10: 42152 | U10: 42152 | V10: 261.8757 | W10: 10 | X10: 379.53 | Y10: 86839 | Z10: =TEXT(Superstone_data[[#This Row],[Order Date]],"mmm") -> May | AA10: =Superstone_data[[#This Row],[Profit]]/Superstone_data[[#This Row],[Sales]] -> 0.69 | AB10: =IFERROR(VLOOKUP(Superstone_data[[#This Row],[Order ID]], Returns!A:B, 2, FALSE), "No") -> No | AC10: =VLOOKUP(Superstone_data[[#This Row],[Region]], Users!A:B, 2, FALSE) -> Erin
A11: 26267 | B11: High | C11: 0.04 | D11: 2.98 | E11: 1.58 | F11: 16 | G11: Sarah Ramsey | H11: Regular Air | I11: Small Business | J11: Office Supplies | K11: Rubber Bands | L11: Wrap Bag | M11: Staples Gold Paper Clips | N11: 0.39 | O11: United States | P11: East | Q11: New York | R11: Syracuse | S11: 13210 | T11: 42047 | U11: 42050 | V11: 2.63 | W11: 6 | X11: 18.8 | Y11: 86836 | Z11: =TEXT(Superstone_data[[#This Row],[Order Date]],"mmm") -> Feb | AA11: =Superstone_data[[#This Row],[Profit]]/Superstone_data[[#This Row],[Sales]] -> 0.13989362 | AB11: =IFERROR(VLOOKUP(Superstone_data[[#This Row],[Order ID]], Returns!A:B, 2, FALSE), "No") -> No | AC11: =VLOOKUP(Superstone_data[[#This Row],[Region]], Users!A:B, 2, FALSE) -> Erin
A12: 26268 | B12: High | C12: 0.05 | D12: 115.99 | E12: 2.5 | F12: 16 | G12: Sarah Ramsey | H12: Regular Air | I12: Small Business | J12: Technology | K12: Telephones and Communication | L12: Small Box | M12: StarTAC 7797 | N12: 0.55 | O12: United States | P12: East | Q12: New York | R12: Syracuse | S12: 13210 | T12: 42047 | U12: 42049 | V12: 652.7331 | W12: 10 | X12: 945.99 | Y12: 86836 | Z12: =TEXT(Superstone_data[[#This Row],[Order Date]],"mmm") -> Feb | AA12: =Superstone_data[[#This Row],[Profit]]/Superstone_data[[#This Row],[Sales]] -> 0.69 | AB12: =IFERROR(VLOOKUP(Superstone_data[[#This Row],[Order ID]], Returns!A:B, 2, FALSE), "No") -> No | AC12: =VLOOKUP(Superstone_data[[#This Row],[Region]], Users!A:B, 2, FALSE) -> Erin
A13: 23890 | B13: High | C13: 0.05 | D13: 26.48 | E13: 6.93 | F13: 18 | G13: Laurie Hanna | H13: Regular Air | I13: Small Business | J13: Furniture | K13: Office Furnishings | L13: Small Box | M13: DAX Natural Wood-Tone Poster Frame | N13: 0.49 | O13: United States | P13: West | Q13: Montana | R13: Helena | S13: 59601 | T13: 42139 | U13: 42140 | V13: 314.4813 | W13: 17 | X13: 455.77 | Y13: 90031 | Z13: =TEXT(Superstone_data[[#This Row],[Order Date]],"mmm") -> May | AA13: =Superstone_data[[#This Row],[Profit]]/Superstone_data[[#This Row],[Sales]] -> 0.69 | AB13: =IFERROR(VLOOKUP(Superstone_data[[#This Row],[Order ID]], Returns!A:B, 2, FALSE), "No") -> No | AC13: =VLOOKUP(Superstone_data[[#This Row],[Region]], Users!A:B, 2, FALSE) -> William
... A182: 19158 | B182: Medium | C182: 0.01 | D182: 29.1 | E182: 4 | F182: 331 | G182: Bradley Pollock | H182: Express Air | I182: Home Office | J182: Technology | K182: Computer Peripherals | L182: Small Box | M182: Acco Keyboard-In-A-Box® | N182: 0.78 | O182: United States | P182: East | Q182: New Hampshire | R182: Goffstown | S182: 3045 | T182: 42108 | U182: 42110 | V182: -22.82 | W182: 8 | X182: 243.32 | Y182: 89726 | Z182: =TEXT(Superstone_data[[#This Row],[Order Date]],"mmm") -> Apr | AA182: =Superstone_data[[#This Row],[Profit]]/Superstone_data[[#This Row],[Sales]] -> -0.093785961 | AB182: =IFERROR(VLOOKUP(Superstone_data[[#This Row],[Order ID]], Returns!A:B, 2, FALSE), "No") -> No | AC182: =VLOOKUP(Superstone_data[[#This Row],[Region]], Users!A:B, 2, FALSE) -> Erin
A183: 18261 | B183: Critical | C183: 0.06 | D183: 276.2 | E183: 24.49 | F183: 335 | G183: Curtis O'Connell | H183: Regular Air | I183: Corporate | J183: Furniture | K183: Chairs & Chairmats | L183: Large Box | M183: SAFCO Arco Folding Chair | O183: United States | P183: West | Q183: Oregon | R183: Medford | S183: 97504 | T183: 42128 | U183: 42129 | V183: 2639.4708 | W183: 14 | X183: 3825.32 | Y183: 87277 | Z183: =TEXT(Superstone_data[[#This Row],[Order Date]],"mmm") -> May | AA183: =Superstone_data[[#This Row],[Profit]]/Superstone_data[[#This Row],[Sales]] -> 0.69 | AB183: =IFERROR(VLOOKUP(Superstone_data[[#This Row],[Order ID]], Returns!A:B, 2, FALSE), "No") -> No | AC183: =VLOOKUP(Superstone_data[[#This Row],[Region]], Users!A:B, 2, FALSE) -> William
A184: 18262 | B184: Critical | C184: 0.09 | D184: 6.28 | E184: 5.29 | F184: 335 | G184: Curtis O'Connell | H184: Regular Air | I184: Corporate | J184: Furniture | K184: Office Furnishings | L184: Small Box | M184: Eldon® 200 Class™ Desk Accessories, Burgundy | N184: 0.43 | O184: United States | P184: West | Q184: Oregon | R184: Medford | S184: 97504 | T184: 42128 | U184: 42128 | V184: -5.2 | W184: 1 | X184: 8.53 | Y184: 87277 | Z184: =TEXT(Superstone_data[[#This Row],[Order Date]],"mmm") -> May | AA184: =Superstone_data[[#This Row],[Profit]]/Superstone_data[[#This Row],[Sales]] -> -0.60961313 | AB184: =IFERROR(VLOOKUP(Superstone_data[[#This Row],[Order ID]], Returns!A:B, 2, FALSE), "No") -> No | AC184: =VLOOKUP(Superstone_data[[#This Row],[Region]], Users!A:B, 2, FALSE) -> William
A185: 23481 | B185: Medium | C185: 0.08 | D185: 7.77 | E185: 9.23 | F185: 339 | G185: Bobby Clements | H185: Regular Air | I185: Corporate | J185: Office Supplies | K185: Appliances | L185: Small Box | M185: Hoover Commercial Soft Guard Upright Vacuum And Disposable Filtration Bags | N185: 0.58 | O185: United States | P185: East | Q185: Ohio | R185: Columbus | S185: 43229 | T185: 42080 | U185: 42081 | V185: -83.65 | W185: 5 | X185: 40.3 | Y185: 90583 | Z185: =TEXT(Superstone_data[[#This Row],[Order Date]],"mmm") -> Mar | AA185: =Superstone_data[[#This Row],[Profit]]/Superstone_data[[#This Row],[Sales]] -> -2.0756824 | AB185: =IFERROR(VLOOKUP(Superstone_data[[#This Row],[Order ID]], Returns!A:B, 2, FALSE), "No") -> No | AC185: =VLOOKUP(Superstone_data[[#This Row],[Region]], Users!A:B, 2, FALSE) -> Erin
A186: 23482 | B186: Medium | C186: 0.07 | D186: 7.59 | E186: 4 | F186: 339 | G186: Bobby Clements | H186: Regular Air | I186: Corporate | J186: Furniture | K186: Office Furnishings | L186: Wrap Bag | M186: Master Giant Foot® Doorstop, Safety Yellow | N186: 0.42 | O186: United States | P186: East | Q186: Ohio | R186: Columbus | S186: 43229 | T186: 42080 | U186: 42082 | V186: 24.39 | W186: 15 | X186: 111.88 | Y186: 90583 | Z186: =TEXT(Superstone_data[[#This Row],[Order Date]],"mmm") -> Mar | AA186: =Superstone_data[[#This Row],[Profit]]/Superstone_data[[#This Row],[Sales]] -> 0.21800143 | AB186: =IFERROR(VLOOKUP(Superstone_data[[#This Row],[Order ID]], Returns!A:B, 2, FALSE), "No") -> No | AC186: =VLOOKUP(Superstone_data[[#This Row],[Region]], Users!A:B, 2, FALSE) -> Erin
A187: 480 | B187: Critical | C187: 0.01 | D187: 3.26 | E187: 1.86 | F187: 342 | G187: Jacqueline Noble | H187: Regular Air | I187: Corporate | J187: Office Supplies | K187: Pens & Art Supplies | L187: Wrap Bag | M187: Avery Hi-Liter GlideStik Fluorescent Highlighter, Yellow Ink | N187: 0.41 | O187: United States | P187: South | Q187: Florida | R187: Miami | S187: 33181 | T187: 42128 | U187: 42130 | V187: -4.6683 | W187: 20 | X187: 73.97 | Y187: 3332 | Z187: =TEXT(Superstone_data[[#This Row],[Order Date]],"mmm") -> May | AA187: =Superstone_data[[#This Row],[Profit]]/Superstone_data[[#This Row],[Sales]] -> -0.063110721 | AB187: =IFERROR(VLOOKUP(Superstone_data[[#This Row],[Order ID]], Returns!A:B, 2, FALSE), "No") -> No | AC187: =VLOOKUP(Superstone_data[[#This Row],[Region]], Users!A:B, 2, FALSE) -> Sam
A188: 22784 | B188: Critical | C188: 0.03 | D188: 15.23 | E188: 27.75 | F188: 343 | G188: Lynn Epstein | H188: Delivery Truck | I188: Corporate | J188: Furniture | K188: Tables | L188: Jumbo Box | M188: Anderson Hickey Conga Table Tops & Accessories | N188: 0.76 | O188: United States | P188: East | Q188: Maine | R188: Bangor | S188: 4401 | T188: 42035 | U188: 42036 | V188: 11.65095 | W188: 7 | X188: 111.86 | Y188: 88151 | Z188: =TEXT(Superstone_data[[#This Row],[Order Date]],"mmm") -> Jan | AA188: =Superstone_data[[#This Row],[Profit]]/Superstone_data[[#This Row],[Sales]] -> 0.10415653 | AB188: =IFERROR(VLOOKUP(Superstone_data[[#This Row],[Order ID]], Returns!A:B, 2, FALSE), "No") -> No | AC188: =VLOOKUP(Superstone_data[[#This Row],[Region]], Users!A:B, 2, FALSE) -> Erin
A189: 18480 | B189: Critical | C189: 0.01 | D189: 3.26 | E189: 1.86 | F189: 344 | G189: Rosemary English | H189: Regular Air | I189: Corporate | J189: Office Supplies | K189: Pens & Art Supplies | L189: Wrap Bag | M189: Avery Hi-Liter GlideStik Fluorescent Highlighter, Yellow Ink | N189: 0.41 | O189: United States | P189: East | Q189: Maine | R189: Portland | S189: 4101 | T189: 42128 | U189: 42130 | V189: 0.702 | W189: 5 | X189: 18.49 | Y189: 88152 | Z189: =TEXT(Superstone_data[[#This Row],[Order Date]],"mmm") -> May | AA189: =Superstone_data[[#This Row],[Profit]]/Superstone_data[[#This Row],[Sales]] -> 0.037966468 | AB189: =IFERROR(VLOOKUP(Superstone_data[[#This Row],[Order ID]], Returns!A:B, 2, FALSE), "No") -> No | AC189: =VLOOKUP(Superstone_data[[#This Row],[Region]], Users!A:B, 2, FALSE) -> Erin
A190: 2408 | B190: Critical | C190: 0 | D190: 8.34 | E190: 2.64 | F190: 349 | G190: Kim Weiss | H190: Express Air | I190: Home Office | J190: Office Supplies | K190: Scissors, Rulers and Trimmers | L190: Small Pack | M190: Acme® Elite Stainless Steel Scissors | N190: 0.59 | O190: United States | P190: South | Q190: Florida | R190: Miami | S190: 33132 | T190: 42164 | U190: 42166 | V190: 5.8625 | W190: 23 | X190: 212.89 | Y190: 17446 | Z190: =TEXT(Superstone_data[[#This Row],[Order Date]],"mmm") -> Jun | AA190: =Superstone_data[[#This Row],[Profit]]/Superstone_data[[#This Row],[Sales]] -> 0.027537696 | AB190: =IFERROR(VLOOKUP(Superstone_data[[#This Row],[Order ID]], Returns!A:B, 2, FALSE), "No") -> No | AC190: =VLOOKUP(Superstone_data[[#This Row],[Region]], Users!A:B, 2, FALSE) -> Sam
A191: 1595 | B191: Medium | C191: 0.04 | D191: 99.23 | E191: 8.99 | F191: 349 | G191: Kim Weiss | H191: Regular Air | I191: Home Office | J191: Furniture | K191: Office Furnishings | L191: Small Pack | M191: GE 48" Fluorescent Tube, Cool White Energy Saver, 34 Watts, 30/Box | N191: 0.35 | O191: United States | P191: South | Q191: Florida | R191: Miami | S191: 33132 | T191: 42006 | U191: 42008 | V191: 1916.6757 | W191: 54 | X191: 5555.6 | Y191: 11527 | Z191: =TEXT(Superstone_data[[#This Row],[Order Date]],"mmm") -> Jan | AA191: =Superstone_data[[#This Row],[Profit]]/Superstone_data[[#This Row],[Sales]] -> 0.34499887 | AB191: =IFERROR(VLOOKUP(Superstone_data[[#This Row],[Order ID]], Returns!A:B, 2, FALSE), "No") -> No | AC191: =VLOOKUP(Superstone_data[[#This Row],[Region]], Users!A:B, 2, FALSE) -> Sam
A192: 20408 | B192: Critical | C192: 0 | D192: 8.34 | E192: 2.64 | F192: 351 | G192: Juanita Coley Knox | H192: Express Air | I192: Home Office | J192: Office Supplies | K192: Scissors, Rulers and Trimmers | L192: Small Pack | M192: Acme® Elite Stainless Steel Scissors | N192: 0.59 | O192: United States | P192: East | Q192: New York | R192: Watertown | S192: 13601 | T192: 42164 | U192: 42166 | V192: 10.5 | W192: 6 | X192: 55.54 | Y192: 88685 | Z192: =TEXT(Superstone_data[[#This Row],[Order Date]],"mmm") -> Jun | AA192: =Superstone_data[[#This Row],[Profit]]/Superstone_data[[#This Row],[Sales]] -> 0.18905293 | AB192: =IFERROR(VLOOKUP(Superstone_data[[#This Row],[Order ID]], Returns!A:B, 2, FALSE), "No") -> No | AC192: =VLOOKUP(Superstone_data[[#This Row],[Region]], Users!A:B, 2, FALSE) -> Erin
A193: 19595 | B193: Medium | C193: 0.04 | D193: 99.23 | E193: 8.99 | F193: 351 | G193: Juanita Coley Knox | H193: Regular Air | I193: Home Office | J193: Furniture | K193: Office Furnishings | L193: Small Pack | M193: GE 48" Fluorescent Tube, Cool White Energy Saver, 34 Watts, 30/Box | N193: 0.35 | O193: United States | P193: East | Q193: New York | R193: Watertown | S193: 13601 | T193: 42006 | U193: 42008 | V193: 993.8346 | W193: 14 | X193: 1440.34 | Y193: 88686 | Z193: =TEXT(Superstone_data[[#This Row],[Order Date]],"mmm") -> Jan | AA193: =Superstone_data[[#This Row],[Profit]]/Superstone_data[[#This Row],[Sales]] -> 0.69 | AB193: =IFERROR(VLOOKUP(Superstone_data[[#This Row],[Order ID]], Returns!A:B, 2, FALSE), "No") -> No | AC193: =VLOOKUP(Superstone_data[[#This Row],[Region]], Users!A:B, 2, FALSE) -> Erin
A194: 19107 | B194: Low | C194: 0.08 | D194: 4.89 | E194: 4.93 | F194: 353 | G194: Bonnie Chambers | H194: Express Air | I194: Home Office | J194: Technology | K194: Computer Peripherals | L194: Small Pack | M194: Maxell 3.5" DS/HD IBM-Formatted Diskettes, 10/Pack | N194: 0.66 | O194: United States | P194: West | Q194: Arizona | R194: Glendale | S194: 85301 | T194: 42138 | U194: 42138 | V194: -165.45 | W194: 17 | X194: 84.76 | Y194: 89647 | Z194: =TEXT(Superstone_data[[#This Row],[Order Date]],"mmm") -> May | AA194: =Superstone_data[[#This Row],[Profit]]/Superstone_data[[#This Row],[Sales]] -> -1.9519821 | AB194: =IFERROR(VLOOKUP(Superstone_data[[#This Row],[Order ID]], Returns!A:B, 2, FALSE), "No") -> No | AC194: =VLOOKUP(Superstone_data[[#This Row],[Region]], Users!A:B, 2, FALSE) -> William
A195: 19108 | B195: Low | C195: 0.07 | D195: 6.68 | E195: 6.92 | F195: 353 | G195: Bonnie Chambers | H195: Regular Air | I195: Home Office | J195: Office Supplies | K195: Paper | L195: Small Box | M195: Xerox 1898 | N195: 0.37 | O195: United States | P195: West | Q195: Arizona | R195: Glendale | S195: 85301 | T195: 42138 | U195: 42145 | V195: -141.12 | W195: 16 | X195: 104.84 | Y195: 89647 | Z195: =TEXT(Superstone_data[[#This Row],[Order Date]],"mmm") -> May | AA195: =Superstone_data[[#This Row],[Profit]]/Superstone_data[[#This Row],[Sales]] -> -1.3460511 | AB195: =IFERROR(VLOOKUP(Superstone_data[[#This Row],[Order ID]], Returns!A:B, 2, FALSE), "No") -> No | AC195: =VLOOKUP(Superstone_data[[#This Row],[Region]], Users!A:B, 2, FALSE) -> William
... A272: 21958 | B272: High | C272: 0.01 | D272: 20.98 | E272: 53.03 | F272: 508 | G272: Cameron Owens | H272: Delivery Truck | I272: Corporate | J272: Office Supplies | K272: Storage & Organization | L272: Jumbo Drum | M272: Tennsco Lockers, Gray | N272: 0.78 | O272: United States | P272: South | Q272: Kentucky | R272: Covington | S272: 41011 | T272: 42058 | U272: 42058 | V272: -282.0818 | W272: 5 | X272: 123 | Y272: 87356 | Z272: =TEXT(Superstone_data[[#This Row],[Order Date]],"mmm") -> Feb | AA272: =Superstone_data[[#This Row],[Profit]]/Superstone_data[[#This Row],[Sales]] -> -2.293348 | AB272: =IFERROR(VLOOKUP(Superstone_data[[#This Row],[Order ID]], Returns!A:B, 2, FALSE), "No") -> No | AC272: =VLOOKUP(Superstone_data[[#This Row],[Region]], Users!A:B, 2, FALSE) -> Sam
A273: 18305 | B273: Critical | C273: 0.01 | D273: 128.24 | E273: 12.65 | F273: 508 | G273: Cameron Owens | H273: Regular Air | I273: Corporate | J273: Furniture | K273: Chairs & Chairmats | L273: Medium Box | M273: SAFCO Folding Chair Trolley | O273: United States | P273: South | Q273: Kentucky | R273: Covington | S273: 41011 | T273: 42112 | U273: 42115 | V273: 140.1354 | W273: 4 | X273: 554.08 | Y273: 87357 | Z273: =TEXT(Superstone_data[[#This Row],[Order Date]],"mmm") -> Apr | AA273: =Superstone_data[[#This Row],[Profit]]/Superstone_data[[#This Row],[Sales]] -> 0.25291546 | AB273: =IFERROR(VLOOKUP(Superstone_data[[#This Row],[Order ID]], Returns!A:B, 2, FALSE), "No") -> No | AC273: =VLOOKUP(Superstone_data[[#This Row],[Region]], Users!A:B, 2, FALSE) -> Sam
A274: 19895 | B274: Low | C274: 0.02 | D274: 48.04 | E274: 5.09 | F274: 510 | G274: Gregory Rao | H274: Regular Air | I274: Corporate | J274: Office Supplies | K274: Paper | L274: Small Box | M274: Xerox 1910 | N274: 0.37 | O274: United States | P274: West | Q274: California | R274: Manteca | S274: 95336 | T274: 42017 | U274: 42017 | V274: 105.2526 | W274: 3 | X274: 152.54 | Y274: 90058 | Z274: =TEXT(Superstone_data[[#This Row],[Order Date]],"mmm") -> Jan | AA274: =Superstone_data[[#This Row],[Profit]]/Superstone_data[[#This Row],[Sales]] -> 0.69 | AB274: =IFERROR(VLOOKUP(Superstone_data[[#This Row],[Order ID]], Returns!A:B, 2, FALSE), "No") -> No | AC274: =VLOOKUP(Superstone_data[[#This Row],[Region]], Users!A:B, 2, FALSE) -> William
A275: 20007 | B275: Critical | C275: 0.03 | D275: 6.37 | E275: 5.19 | F275: 510 | G275: Gregory Rao | H275: Regular Air | I275: Corporate | J275: Office Supplies | K275: Binders and Binder Accessories | L275: Small Box | M275: C-Line Peel & Stick Add-On Filing Pockets, 8-3/4 x 5-1/8, 10/Pack | N275: 0.38 | O275: United States | P275: West | Q275: California | R275: Manteca | S275: 95336 | T275: 42036 | U275: 42037 | V275: -29.0927 | W275: 14 | X275: 89.79 | Y275: 90059 | Z275: =TEXT(Superstone_data[[#This Row],[Order Date]],"mmm") -> Feb | AA275: =Superstone_data[[#This Row],[Profit]]/Superstone_data[[#This Row],[Sales]] -> -0.32400824 | AB275: =IFERROR(VLOOKUP(Superstone_data[[#This Row],[Order ID]], Returns!A:B, 2, FALSE), "No") -> No | AC275: =VLOOKUP(Superstone_data[[#This Row],[Region]], Users!A:B, 2, FALSE) -> William
A276: 20216 | B276: Low | C276: 0.07 | D276: 12.64 | E276: 4.98 | F276: 518 | G276: Mark Ritchie | H276: Regular Air | I276: Home Office | J276: Furniture | K276: Office Furnishings | L276: Small Pack | M276: Nu-Dell Executive Frame | N276: 0.48 | O276: United States | P276: Central | Q276: Missouri | R276: Clayton | S276: 63105 | T276: 42160 | U276: 42167 | V276: 113.415 | W276: 16 | X276: 199.76 | Y276: 90867 | Z276: =TEXT(Superstone_data[[#This Row],[Order Date]],"mmm") -> Jun | AA276: =Superstone_data[[#This Row],[Profit]]/Superstone_data[[#This Row],[Sales]] -> 0.56775631 | AB276: =IFERROR(VLOOKUP(Superstone_data[[#This Row],[Order ID]], Returns!A:B, 2, FALSE), "No") -> No | AC276: =VLOOKUP(Superstone_data[[#This Row],[Region]], Users!A:B, 2, FALSE) -> Chris
A277: 23200 | B277: Medium | C277: 0.02 | D277: 150.98 | E277: 13.99 | F277: 522 | G277: Aaron Riggs | H277: Express Air | I277: Small Business | J277: Technology | K277: Office Machines | L277: Medium Box | M277: Canon MP41DH Printing Calculator | N277: 0.38 | O277: United States | P277: West | Q277: Oregon | R277: Redmond | S277: 97756 | T277: 42177 | U277: 42179 | V277: 26.1 | W277: 3 | X277: 480.37 | Y277: 89327 | Z277: =TEXT(Superstone_data[[#This Row],[Order Date]],"mmm") -> Jun | AA277: =Superstone_data[[#This Row],[Profit]]/Superstone_data[[#This Row],[Sales]] -> 0.054333118 | AB277: =IFERROR(VLOOKUP(Superstone_data[[#This Row],[Order ID]], Returns!A:B, 2, FALSE), "No") -> No | AC277: =VLOOKUP(Superstone_data[[#This Row],[Region]], Users!A:B, 2, FALSE) -> William
A278: 23201 | B278: Medium | C278: 0.1 | D278: 5.43 | E278: 0.95 | F278: 522 | G278: Aaron Riggs | H278: Regular Air | I278: Small Business | J278: Office Supplies | K278: Paper | L278: Wrap Bag | M278: Wirebound Message Book, 4 per Page | N278: 0.36 | O278: United States | P278: West | Q278: Oregon | R278: Redmond | S278: 97756 | T278: 42177 | U278: 42179 | V278: -2.58 | W278: 1 | X278: 5.76 | Y278: 89327 | Z278: =TEXT(Superstone_data[[#This Row],[Order Date]],"mmm") -> Jun | AA278: =Superstone_data[[#This Row],[Profit]]/Superstone_data[[#This Row],[Sales]] -> -0.44791667 | AB278: =IFERROR(VLOOKUP(Superstone_data[[#This Row],[Order ID]], Returns!A:B, 2, FALSE), "No") -> No | AC278: =VLOOKUP(Superstone_data[[#This Row],[Region]], Users!A:B, 2, FALSE) -> William
A279: 23202 | B279: Medium | C279: 0.01 | D279: 179.29 | E279: 29.21 | F279: 522 | G279: Aaron Riggs | H279: Delivery Truck | I279: Small Business | J279: Furniture | K279: Tables | L279: Jumbo Box | M279: Bevis Round Conference Table Top, X-Base | N279: 0.74 | O279: United States | P279: West | Q279: Oregon | R279: Redmond | S279: 97756 | T279: 42177 | U279: 42178 | V279: 2800.12 | W279: 21 | X279: 3112.13 | Y279: 89327 | Z279: =TEXT(Superstone_data[[#This Row],[Order Date]],"mmm") -> Jun | AA279: =Superstone_data[[#This Row],[Profit]]/Superstone_data[[#This Row],[Sales]] -> 0.89974391 | AB279: =IFERROR(VLOOKUP(Superstone_data[[#This Row],[Order ID]], Returns!A:B, 2, FALSE), "No") -> No | AC279: =VLOOKUP(Superstone_data[[#This Row],[Region]], Users!A:B, 2, FALSE) -> William
A280: 21517 | B280: Not Specified | C280: 0.03 | D280: 1270.99 | E280: 19.99 | F280: 524 | G280: Gina McKnight | H280: Regular Air | I280: Consumer | J280: Office Supplies | K280: Binders and Binder Accessories | L280: Small Box | M280: Fellowes PB500 Electric Punch Plastic Comb Binding Machine with Manual Bind | N280: 0.35 | O280: United States | P280: South | Q280: Tennessee | R280: Farragut | S280: 37922 | T280: 42024 | U280: 42026 | V280: 363.552 | W280: 2 | X280: 2589.01 | Y280: 91127 | Z280: =TEXT(Superstone_data[[#This Row],[Order Date]],"mmm") -> Jan | AA280: =Superstone_data[[#This Row],[Profit]]/Superstone_data[[#This Row],[Sales]] -> 0.14042124 | AB280: =IFERROR(VLOOKUP(Superstone_data[[#This Row],[Order ID]], Returns!A:B, 2, FALSE), "No") -> No | AC280: =VLOOKUP(Superstone_data[[#This Row],[Region]], Users!A:B, 2, FALSE) -> Sam
A281: 21518 | B281: Not Specified | C281: 0.07 | D281: 2036.48 | E281: 14.7 | F281: 524 | G281: Gina McKnight | H281: Delivery Truck | I281: Consumer | J281: Technology | K281: Office Machines | L281: Jumbo Drum | M281: Lexmark 4227 Plus Dot Matrix Printer | N281: 0.55 | O281: United States | P281: South | Q281: Tennessee | R281: Farragut | S281: 37922 | T281: 42024 | U281: 42026 | V281: -11.536 | W281: 1 | X281: 1893.93 | Y281: 91127 | Z281: =TEXT(Superstone_data[[#This Row],[Order Date]],"mmm") -> Jan | AA281: =Superstone_data[[#This Row],[Profit]]/Superstone_data[[#This Row],[Sales]] -> -0.0060910382 | AB281: =IFERROR(VLOOKUP(Superstone_data[[#This Row],[Order ID]], Returns!A:B, 2, FALSE), "No") -> No | AC281: =VLOOKUP(Superstone_data[[#This Row],[Region]], Users!A:B, 2, FALSE) -> Sam
A282: 22176 | B282: High | C282: 0.09 | D282: 17.98 | E282: 8.51 | F282: 526 | G282: April Hu | H282: Regular Air | I282: Home Office | J282: Technology | K282: Office Machines | L282: Medium Box | M282: Canon P1-DHIII Palm Printing Calculator | N282: 0.4 | O282: United States | P282: West | Q282: Arizona | R282: Mesa | S282: 85204 | T282: 42149 | U282: 42151 | V282: -6.612 | W282: 12 | X282: 211.13 | Y282: 90026 | Z282: =TEXT(Superstone_data[[#This Row],[Order Date]],"mmm") -> May | AA282: =Superstone_data[[#This Row],[Profit]]/Superstone_data[[#This Row],[Sales]] -> -0.031317198 | AB282: =IFERROR(VLOOKUP(Superstone_data[[#This Row],[Order ID]], Returns!A:B, 2, FALSE), "No") -> No | AC282: =VLOOKUP(Superstone_data[[#This Row],[Region]], Users!A:B, 2, FALSE) -> William
A283: 20494 | B283: Not Specified | C283: 0 | D283: 1.88 | E283: 1.49 | F283: 526 | G283: April Hu | H283: Regular Air | I283: Home Office | J283: Office Supplies | K283: Binders and Binder Accessories | L283: Small Box | M283: Staples® General Use 3-Ring Binders | N283: 0.37 | O283: United States | P283: West | Q283: Arizona | R283: Mesa | S283: 85204 | T283: 42021 | U283: 42022 | V283: -15.5595 | W283: 13 | X283: 25.39 | Y283: 90027 | Z283: =TEXT(Superstone_data[[#This Row],[Order Date]],"mmm") -> Jan | AA283: =Superstone_data[[#This Row],[Profit]]/Superstone_data[[#This Row],[Sales]] -> -0.61282001 | AB283: =IFERROR(VLOOKUP(Superstone_data[[#This Row],[Order ID]], Returns!A:B, 2, FALSE), "No") -> No | AC283: =VLOOKUP(Superstone_data[[#This Row],[Region]], Users!A:B, 2, FALSE) -> William
A284: 20495 | B284: Not Specified | C284: 0.06 | D284: 5.78 | E284: 5.67 | F284: 526 | G284: April Hu | H284: Regular Air | I284: Home Office | J284: Office Supplies | K284: Paper | L284: Small Box | M284: Xerox 1978 | N284: 0.36 | O284: United States | P284: West | Q284: Arizona | R284: Mesa | S284: 85204 | T284: 42021 | U284: 42022 | V284: -108.19 | W284: 15 | X284: 87.27 | Y284: 90027 | Z284: =TEXT(Superstone_data[[#This Row],[Order Date]],"mmm") -> Jan | AA284: =Superstone_data[[#This Row],[Profit]]/Superstone_data[[#This Row],[Sales]] -> -1.2397158 | AB284: =IFERROR(VLOOKUP(Superstone_data[[#This Row],[Order ID]], Returns!A:B, 2, FALSE), "No") -> No | AC284: =VLOOKUP(Superstone_data[[#This Row],[Region]], Users!A:B, 2, FALSE) -> William
...

Sheet Returns
A1: Order ID | B1: Status
A2: 65 | B2: Returned
A3: 612 | B3: Returned
A4: 614 | B4: Returned
A5: 678 | B5: Returned
A6: 710 | B6: Returned
A7: 740 | B7: Returned
A8: 775 | B8: Returned
A9: 833 | B9: Returned
A10: 902 | B10: Returned
A11: 3300 | B11: Returned
A12: 3456 | B12: Returned
A13: 3525 | B13: Returned
... A1635: 182906 | B1635: Returned

Sheet Users
A1: Region | B1: Manager
A2: Central | B2: Chris
A3: East | B3: Erin
A4: South | B4: Sam
A5: West | B5: William

Sheet Pivots
A12: Average of Profit margin
A13: -0.33326229
A15: Total Profit | B15: Total Sales
A16: 85291.403 | B16: 592171.49 | D16: Row Labels | E16: Sum of Profit
D17: Apr | E17: 39562.479
A18: Count of Order ID | D18: Feb | E18: -3273.2288
A19: 474 | D19: Jan | E19: -7866.8671
D20: Jun | E20: 28420.945
D21: Mar | E21: 13182.673
D22: May | E22: 15265.402
A23: Row Labels | B23: Sum of Sales | D23: Grand Total | E23: 85291.403
A24: Jun | B24: 123225.09
A25: May | B25: 84858.81
A26: Apr | B26: 189208.29 | D26: Row Labels | E26: Total Profit
A27: Mar | B27: 59137.04 | D27: Furniture | E27: -462.97419
A28: Feb | B28: 69708.83 | D28: Office Supplies | E28: 51107.563
A29: Jan | B29: 66033.43 | D29: Technology | E29: 34646.815
A30: Grand Total | B30: 592171.49 | D30: Grand Total | E30: 85291.403
A36: Row Labels | B36: Count of Returned
A37: Furniture | B37: 99
A38: Office Supplies | B38: 265
A39: Technology | B39: 110
A40: Grand Total | B40: 474
A44: Row Labels | B44: Sum of Profit
A45: Rhode Island | B45: 5073.0014
A46: Massachusetts | B46: 5293.784
A47: District of Columbia | B47: 11677.363
A48: Ohio | B48: 23410.842
A49: New York | B49: 27611.943
A50: Grand Total | B50: 73066.934
A53: Row Labels | B53: Total Profit
A54: Pennsylvania | B54: -1095.5065
A55: Connecticut | B55: -529.1063
A56: Delaware | B56: 406.7418
A57: Vermont | B57: 530.14978
A58: New Jersey | B58: 770.90869
A59: Grand Total | B59: 83.187443

Sheet Dashboard
